Workbook
Name IDs_Clientes_Validos: #REF!
Name IDs_Productos_Validos: #REF!
Name ListaClientes: #REF!
Name RangoHistorico: OFFSET(#REF!,0,0,COUNTA(#REF!),8)
Name SegmentaciónDeDatos_Cliente: #N/A
Name SegmentaciónDeDatos_Mes: #N/A
Name SegmentaciónDeDatos_Producto: #N/A

Sheet Resumen Ejecutivo
A1: Checkpoint — Modelo BI de Ventas
A3: Flujo documentado: ETL (M) → Modelo estrella → DAX → Estadística → Escenarios
A5: KPI | B5: Resultado | D5: Cobertura del modelo | E5: Estado
A6: Registros | B6: =COUNTA('Dataset Principal'!B2:B5001) -> 5000 | D6: ETL y código M | E6: Implementado
A7: Ventas totales | B7: =SUM('Dataset Principal'!I2:I5001) -> 6.3295482e+08 | D7: Modelo estrella 1:N | E7: Implementado
A8: Margen neto estimado | B8: =SUM('Dataset Principal'!K2:K5001) -> 1.8988645e+08 | D8: DAX con VAR/RETURN | E8: Implementado
A9: Margen neto % | B9: =B8/B7 -> 0.3 | D9: Estadística y escenarios | E9: Implementado
A12: Hallazgos
A13: Las ventas suman $632,95 millones en 5.000 operaciones.
A14: Con costo estimado en 70%, el margen neto modelado es 30% de ventas.
A15: La media supera la mediana, señal de operaciones grandes que elevan el promedio.
A16: El objetivo de $5 millones se calcula con el margen unitario base.
A18: Nota de implementación
A19: Flujo implementado: consulta Power Query, tablas en el Modelo de datos, relaciones 1:N, medidas DAX, reporte ToolPak, escenarios y Buscar objetivo.

Sheet Tbl_Dataset
A1: Fecha_Operacion | B1: ID_Transaccion | C1: Bultos | D1: Precio_Mayorista | E1: Impuesto_Interno | F1: ID_Cliente | G1: ID_Producto | H1: Mes_Operacion | I1: Venta_Total | J1: Costo_Estimado | K1: Margen_Neto
A2: 46252 | B2: TX-100000 | C2: 6 | D2: 3044 | E2: 0.04 | F2: 2 | G2: 1 | H2: 1/8/2026 00:00:00 | I2: 18994.56 | J2: 13296.192 | K2: 5698.368
A3: 46149 | B3: TX-100001 | C3: 5 | D3: 12534 | E3: 0.11 | F3: 4 | G3: 2 | H3: 1/5/2026 00:00:00 | I3: 69563.7 | J3: 48694.59 | K3: 20869.11
A4: 46075 | B4: TX-100002 | C4: 2 | D4: 10179 | E4: 0.15 | F4: 4 | G4: 3 | H4: 1/2/2026 00:00:00 | I4: 23411.7 | J4: 16388.19 | K4: 7023.51
A5: 46126 | B5: TX-100003 | C5: 9 | D5: 2075 | E5: 0.09 | F5: 4 | G5: 4 | H5: 1/4/2026 00:00:00 | I5: 20355.75 | J5: 14249.025 | K5: 6106.725
A6: 46185 | B6: TX-100004 | C6: 3 | D6: 25407 | E6: 0.08 | F6: 5 | G6: 5 | H6: 1/6/2026 00:00:00 | I6: 82318.68 | J6: 57623.076 | K6: 24695.604
A7: 46386 | B7: TX-100005 | C7: 8 | D7: 32401 | E7: 0.15 | F7: 2 | G7: 6 | H7: 1/12/2026 00:00:00 | I7: 298089.2 | J7: 208662.44 | K7: 89426.76
A8: 46336 | B8: TX-100006 | C8: 4 | D8: 33553 | E8: 0.06 | F8: 1 | G8: 5 | H8: 1/11/2026 00:00:00 | I8: 142264.72 | J8: 99585.304 | K8: 42679.416
A9: 46238 | B9: TX-100007 | C9: 6 | D9: 5774 | F9: 5 | G9: 5 | H9: 1/8/2026 00:00:00 | I9: 34644 | J9: 24250.8 | K9: 10393.2
A10: 46372 | B10: TX-100008 | C10: 11 | D10: 21789 | F10: 1 | G10: 6 | H10: 1/12/2026 00:00:00 | I10: 239679 | J10: 167775.3 | K10: 71903.7
A11: 46268 | B11: TX-100009 | C11: 1 | D11: 31120 | E11: 0.11 | F11: 5 | G11: 2 | H11: 1/9/2026 00:00:00 | I11: 34543.2 | J11: 24180.24 | K11: 10362.96
A12: 46168 | B12: TX-100010 | C12: 5 | D12: 18941 | F12: 5 | G12: 5 | H12: 1/5/2026 00:00:00 | I12: 94705 | J12: 66293.5 | K12: 28411.5
A13: 46280 | B13: TX-100011 | C13: 5 | D13: 6089 | E13: 0.03 | F13: 1 | G13: 7 | H13: 1/9/2026 00:00:00 | I13: 31358.35 | J13: 21950.845 | K13: 9407.505
A14: 46211 | B14: TX-100012 | C14: 8 | D14: 30535 | E14: 0.12 | F14: 4 | G14: 2 | H14: 1/7/2026 00:00:00 | I14: 273593.6 | J14: 191515.52 | K14: 82078.08
A15: 46278 | B15: TX-100013 | C15: 10 | D15: 25346 | E15: 0.05 | F15: 5 | G15: 1 | H15: 1/9/2026 00:00:00 | I15: 266133 | J15: 186293.1 | K15: 79839.9
A16: 46176 | B16: TX-100014 | C16: 4 | D16: 2299 | E16: 0.03 | F16: 2 | G16: 1 | H16: 1/6/2026 00:00:00 | I16: 9471.88 | J16: 6630.316 | K16: 2841.564
A17: 46301 | B17: TX-100015 | C17: 10 | D17: 3179 | F17: 5 | G17: 4 | H17: 1/10/2026 00:00:00 | I17: 31790 | J17: 22253 | K17: 9537
A18: 46095 | B18: TX-100016 | C18: 7 | D18: 16266 | E18: 0.12 | F18: 4 | G18: 3 | H18: 1/3/2026 00:00:00 | I18: 127525.44 | J18: 89267.808 | K18: 38257.632
A19: 46301 | B19: TX-100017 | C19: 3 | D19: 16742 | E19: 0.11 | F19: 5 | G19: 3 | H19: 1/10/2026 00:00:00 | I19: 55750.86 | J19: 39025.602 | K19: 16725.258
A20: 46061 | B20: TX-100018 | C20: 2 | D20: 13533 | E20: 0.14 | F20: 3 | G20: 8 | H20: 1/2/2026 00:00:00 | I20: 30855.24 | J20: 21598.668 | K20: 9256.572
A21: 46158 | B21: TX-100019 | C21: 1 | D21: 5105 | E21: 0.09 | F21: 3 | G21: 7 | H21: 1/5/2026 00:00:00 | I21: 5564.45 | J21: 3895.115 | K21: 1669.335
A22: 46132 | B22: TX-100020 | C22: 10 | D22: 16885 | E22: 0.06 | F22: 2 | G22: 1 | H22: 1/4/2026 00:00:00 | I22: 178981 | J22: 125286.7 | K22: 53694.3
A23: 46316 | B23: TX-100021 | C23: 1 | D23: 13092 | F23: 1 | G23: 1 | H23: 1/10/2026 00:00:00 | I23: 13092 | J23: 9164.4 | K23: 3927.6
A24: 46303 | B24: TX-100022 | C24: 10 | D24: 26368 | F24: 3 | G24: 8 | H24: 1/10/2026 00:00:00 | I24: 263680 | J24: 184576 | K24: 79104
A25: 46265 | B25: TX-100023 | C25: 10 | D25: 21385 | F25: 4 | G25: 4 | H25: 1/8/2026 00:00:00 | I25: 213850 | J25: 149695 | K25: 64155
A26: 46229 | B26: TX-100024 | C26: 5 | D26: 23388 | F26: 2 | G26: 3 | H26: 1/7/2026 00:00:00 | I26: 116940 | J26: 81858 | K26: 35082
A27: 46126 | B27: TX-100025 | C27: 12 | D27: 2582 | E27: 0.05 | F27: 1 | G27: 6 | H27: 1/4/2026 00:00:00 | I27: 32533.2 | J27: 22773.24 | K27: 9759.96
A28: 46086 | B28: TX-100026 | C28: 2 | D28: 13067 | F28: 2 | G28: 2 | H28: 1/3/2026 00:00:00 | I28: 26134 | J28: 18293.8 | K28: 7840.2
A29: 46135 | B29: TX-100027 | C29: 8 | D29: 23563 | F29: 4 | G29: 7 | H29: 1/4/2026 00:00:00 | I29: 188504 | J29: 131952.8 | K29: 56551.2
A30: 46291 | B30: TX-100028 | C30: 10 | D30: 24849 | E30: 0.15 | F30: 4 | G30: 8 | H30: 1/9/2026 00:00:00 | I30: 285763.5 | J30: 200034.45 | K30: 85729.05
A31: 46058 | B31: TX-100029 | C31: 11 | D31: 20283 | E31: 0.12 | F31: 2 | G31: 6 | H31: 1/2/2026 00:00:00 | I31: 249886.56 | J31: 174920.59 | K31: 74965.968
A32: 46077 | B32: TX-100030 | C32: 12 | D32: 17890 | E32: 0.09 | F32: 1 | G32: 4 | H32: 1/2/2026 00:00:00 | I32: 234001.2 | J32: 163800.84 | K32: 70200.36
A33: 46199 | B33: TX-100031 | C33: 4 | D33: 6009 | E33: 0.09 | F33: 4 | G33: 2 | H33: 1/6/2026 00:00:00 | I33: 26199.24 | J33: 18339.468 | K33: 7859.772
A34: 46344 | B34: TX-100032 | C34: 11 | D34: 23552 | E34: 0.04 | F34: 2 | G34: 1 | H34: 1/11/2026 00:00:00 | I34: 269434.88 | J34: 188604.42 | K34: 80830.464
A35: 46181 | B35: TX-100033 | C35: 4 | D35: 27730 | F35: 5 | G35: 4 | H35: 1/6/2026 00:00:00 | I35: 110920 | J35: 77644 | K35: 33276
A36: 46115 | B36: TX-100034 | C36: 6 | D36: 11824 | F36: 4 | G36: 2 | H36: 1/4/2026 00:00:00 | I36: 70944 | J36: 49660.8 | K36: 21283.2
A37: 46128 | B37: TX-100035 | C37: 4 | D37: 16635 | E37: 0.02 | F37: 3 | G37: 1 | H37: 1/4/2026 00:00:00 | I37: 67870.8 | J37: 47509.56 | K37: 20361.24
A38: 46365 | B38: TX-100036 | C38: 1 | D38: 24659 | E38: 0.1 | F38: 1 | G38: 3 | H38: 1/12/2026 00:00:00 | I38: 27124.9 | J38: 18987.43 | K38: 8137.47
A39: 46094 | B39: TX-100037 | C39: 1 | D39: 25492 | E39: 0.07 | F39: 3 | G39: 5 | H39: 1/3/2026 00:00:00 | I39: 27276.44 | J39: 19093.508 | K39: 8182.932
A40: 46381 | B40: TX-100038 | C40: 4 | D40: 15290 | E40: 0.05 | F40: 5 | G40: 8 | H40: 1/12/2026 00:00:00 | I40: 64218 | J40: 44952.6 | K40: 19265.4
...

Sheet ToolPak Estadística
A1: Columna1
A3: Media | B3: 126590.96
A4: Error típico | B4: 1414.1501
A5: Mediana | B5: 99448.12
A6: Moda | B6: 31790
A7: Desviación estándar | B7: 99995.514
A8: Varianza de la muestra | B8: 9.9991027e+09
A9: Curtosis | B9: 0.075501368
A10: Coeficiente de asimetría | B10: 0.90954954
A11: Rango | B11: 472735
A12: Mínimo | B12: 1619
A13: Máximo | B13: 474354
A14: Suma | B14: 6.3295482e+08
A15: Cuenta | B15: 5000

Sheet Dataset Principal
A1: Fecha_Operacion | B1: ID_Transaccion | C1: Bultos | D1: Precio_Mayorista | E1: Impuesto_Interno | F1: ID_Cliente | G1: ID_Producto | H1: Mes_Operacion | I1: Venta_Total | J1: Costo_Estimado | K1: Margen_Neto
A2: 46252 | B2: TX-100000 | C2: 6 | D2: 3044 | E2: 0.04 | F2: 2 | G2: 1 | H2: =DATE(YEAR($A2),MONTH($A2),1) -> 46235 | I2: =$C2*$D2*(1+$E2) -> 18994.56 | J2: =I2*70% -> 13296.192 | K2: =I2-J2 -> 5698.368
A3: 46149 | B3: TX-100001 | C3: 5 | D3: 12534 | E3: 0.11 | F3: 4 | G3: 2 | H3: =DATE(YEAR($A3),MONTH($A3),1) -> 46143 | I3: =$C3*$D3*(1+$E3) -> 69563.7 | J3: =I3*70% -> 48694.59 | K3: =I3-J3 -> 20869.11
A4: 46075 | B4: TX-100002 | C4: 2 | D4: 10179 | E4: 0.15 | F4: 4 | G4: 3 | H4: =DATE(YEAR($A4),MONTH($A4),1) -> 46054 | I4: =$C4*$D4*(1+$E4) -> 23411.7 | J4: =I4*70% -> 16388.19 | K4: =I4-J4 -> 7023.51
A5: 46126 | B5: TX-100003 | C5: 9 | D5: 2075 | E5: 0.09 | F5: 4 | G5: 4 | H5: =DATE(YEAR($A5),MONTH($A5),1) -> 46113 | I5: =$C5*$D5*(1+$E5) -> 20355.75 | J5: =I5*70% -> 14249.025 | K5: =I5-J5 -> 6106.725
A6: 46185 | B6: TX-100004 | C6: 3 | D6: 25407 | E6: 0.08 | F6: 5 | G6: 5 | H6: =DATE(YEAR($A6),MONTH($A6),1) -> 46174 | I6: =$C6*$D6*(1+$E6) -> 82318.68 | J6: =I6*70% -> 57623.076 | K6: =I6-J6 -> 24695.604
A7: 46386 | B7: TX-100005 | C7: 8 | D7: 32401 | E7: 0.15 | F7: 2 | G7: 6 | H7: =DATE(YEAR($A7),MONTH($A7),1) -> 46357 | I7: =$C7*$D7*(1+$E7) -> 298089.2 | J7: =I7*70% -> 208662.44 | K7: =I7-J7 -> 89426.76
A8: 46336 | B8: TX-100006 | C8: 4 | D8: 33553 | E8: 0.06 | F8: 1 | G8: 5 | H8: =DATE(YEAR($A8),MONTH($A8),1) -> 46327 | I8: =$C8*$D8*(1+$E8) -> 142264.72 | J8: =I8*70% -> 99585.304 | K8: =I8-J8 -> 42679.416
A9: 46238 | B9: TX-100007 | C9: 6 | D9: 5774 | F9: 5 | G9: 5 | H9: =DATE(YEAR($A9),MONTH($A9),1) -> 46235 | I9: =$C9*$D9*(1+$E9) -> 34644 | J9: =I9*70% -> 24250.8 | K9: =I9-J9 -> 10393.2
A10: 46372 | B10: TX-100008 | C10: 11 | D10: 21789 | F10: 1 | G10: 6 | H10: =DATE(YEAR($A10),MONTH($A10),1) -> 46357 | I10: =$C10*$D10*(1+$E10) -> 239679 | J10: =I10*70% -> 167775.3 | K10: =I10-J10 -> 71903.7
A11: 46268 | B11: TX-100009 | C11: 1 | D11: 31120 | E11: 0.11 | F11: 5 | G11: 2 | H11: =DATE(YEAR($A11),MONTH($A11),1) -> 46266 | I11: =$C11*$D11*(1+$E11) -> 34543.2 | J11: =I11*70% -> 24180.24 | K11: =I11-J11 -> 10362.96
A12: 46168 | B12: TX-100010 | C12: 5 | D12: 18941 | F12: 5 | G12: 5 | H12: =DATE(YEAR($A12),MONTH($A12),1) -> 46143 | I12: =$C12*$D12*(1+$E12) -> 94705 | J12: =I12*70% -> 66293.5 | K12: =I12-J12 -> 28411.5
A13: 46280 | B13: TX-100011 | C13: 5 | D13: 6089 | E13: 0.03 | F13: 1 | G13: 7 | H13: =DATE(YEAR($A13),MONTH($A13),1) -> 46266 | I13: =$C13*$D13*(1+$E13) -> 31358.35 | J13: =I13*70% -> 21950.845 | K13: =I13-J13 -> 9407.505
A14: 46211 | B14: TX-100012 | C14: 8 | D14: 30535 | E14: 0.12 | F14: 4 | G14: 2 | H14: =DATE(YEAR($A14),MONTH($A14),1) -> 46204 | I14: =$C14*$D14*(1+$E14) -> 273593.6 | J14: =I14*70% -> 191515.52 | K14: =I14-J14 -> 82078.08
A15: 46278 | B15: TX-100013 | C15: 10 | D15: 25346 | E15: 0.05 | F15: 5 | G15: 1 | H15: =DATE(YEAR($A15),MONTH($A15),1) -> 46266 | I15: =$C15*$D15*(1+$E15) -> 266133 | J15: =I15*70% -> 186293.1 | K15: =I15-J15 -> 79839.9
A16: 46176 | B16: TX-100014 | C16: 4 | D16: 2299 | E16: 0.03 | F16: 2 | G16: 1 | H16: =DATE(YEAR($A16),MONTH($A16),1) -> 46174 | I16: =$C16*$D16*(1+$E16) -> 9471.88 | J16: =I16*70% -> 6630.316 | K16: =I16-J16 -> 2841.564
A17: 46301 | B17: TX-100015 | C17: 10 | D17: 3179 | F17: 5 | G17: 4 | H17: =DATE(YEAR($A17),MONTH($A17),1) -> 46296 | I17: =$C17*$D17*(1+$E17) -> 31790 | J17: =I17*70% -> 22253 | K17: =I17-J17 -> 9537
A18: 46095 | B18: TX-100016 | C18: 7 | D18: 16266 | E18: 0.12 | F18: 4 | G18: 3 | H18: =DATE(YEAR($A18),MONTH($A18),1) -> 46082 | I18: =$C18*$D18*(1+$E18) -> 127525.44 | J18: =I18*70% -> 89267.808 | K18: =I18-J18 -> 38257.632
A19: 46301 | B19: TX-100017 | C19: 3 | D19: 16742 | E19: 0.11 | F19: 5 | G19: 3 | H19: =DATE(YEAR($A19),MONTH($A19),1) -> 46296 | I19: =$C19*$D19*(1+$E19) -> 55750.86 | J19: =I19*70% -> 39025.602 | K19: =I19-J19 -> 16725.258
A20: 46061 | B20: TX-100018 | C20: 2 | D20: 13533 | E20: 0.14 | F20: 3 | G20: 8 | H20: =DATE(YEAR($A20),MONTH($A20),1) -> 46054 | I20: =$C20*$D20*(1+$E20) -> 30855.24 | J20: =I20*70% -> 21598.668 | K20: =I20-J20 -> 9256.572
A21: 46158 | B21: TX-100019 | C21: 1 | D21: 5105 | E21: 0.09 | F21: 3 | G21: 7 | H21: =DATE(YEAR($A21),MONTH($A21),1) -> 46143 | I21: =$C21*$D21*(1+$E21) -> 5564.45 | J21: =I21*70% -> 3895.115 | K21: =I21-J21 -> 1669.335
A22: 46132 | B22: TX-100020 | C22: 10 | D22: 16885 | E22: 0.06 | F22: 2 | G22: 1 | H22: =DATE(YEAR($A22),MONTH($A22),1) -> 46113 | I22: =$C22*$D22*(1+$E22) -> 178981 | J22: =I22*70% -> 125286.7 | K22: =I22-J22 -> 53694.3
A23: 46316 | B23: TX-100021 | C23: 1 | D23: 13092 | F23: 1 | G23: 1 | H23: =DATE(YEAR($A23),MONTH($A23),1) -> 46296 | I23: =$C23*$D23*(1+$E23) -> 13092 | J23: =I23*70% -> 9164.4 | K23: =I23-J23 -> 3927.6
A24: 46303 | B24: TX-100022 | C24: 10 | D24: 26368 | F24: 3 | G24: 8 | H24: =DATE(YEAR($A24),MONTH($A24),1) -> 46296 | I24: =$C24*$D24*(1+$E24) -> 263680 | J24: =I24*70% -> 184576 | K24: =I24-J24 -> 79104
A25: 46265 | B25: TX-100023 | C25: 10 | D25: 21385 | F25: 4 | G25: 4 | H25: =DATE(YEAR($A25),MONTH($A25),1) -> 46235 | I25: =$C25*$D25*(1+$E25) -> 213850 | J25: =I25*70% -> 149695 | K25: =I25-J25 -> 64155
A26: 46229 | B26: TX-100024 | C26: 5 | D26: 23388 | F26: 2 | G26: 3 | H26: =DATE(YEAR($A26),MONTH($A26),1) -> 46204 | I26: =$C26*$D26*(1+$E26) -> 116940 | J26: =I26*70% -> 81858 | K26: =I26-J26 -> 35082
A27: 46126 | B27: TX-100025 | C27: 12 | D27: 2582 | E27: 0.05 | F27: 1 | G27: 6 | H27: =DATE(YEAR($A27),MONTH($A27),1) -> 46113 | I27: =$C27*$D27*(1+$E27) -> 32533.2 | J27: =I27*70% -> 22773.24 | K27: =I27-J27 -> 9759.96
A28: 46086 | B28: TX-100026 | C28: 2 | D28: 13067 | F28: 2 | G28: 2 | H28: =DATE(YEAR($A28),MONTH($A28),1) -> 46082 | I28: =$C28*$D28*(1+$E28) -> 26134 | J28: =I28*70% -> 18293.8 | K28: =I28-J28 -> 7840.2
A29: 46135 | B29: TX-100027 | C29: 8 | D29: 23563 | F29: 4 | G29: 7 | H29: =DATE(YEAR($A29),MONTH($A29),1) -> 46113 | I29: =$C29*$D29*(1+$E29) -> 188504 | J29: =I29*70% -> 131952.8 | K29: =I29-J29 -> 56551.2
A30: 46291 | B30: TX-100028 | C30: 10 | D30: 24849 | E30: 0.15 | F30: 4 | G30: 8 | H30: =DATE(YEAR($A30),MONTH($A30),1) -> 46266 | I30: =$C30*$D30*(1+$E30) -> 285763.5 | J30: =I30*70% -> 200034.45 | K30: =I30-J30 -> 85729.05
A31: 46058 | B31: TX-100029 | C31: 11 | D31: 20283 | E31: 0.12 | F31: 2 | G31: 6 | H31: =DATE(YEAR($A31),MONTH($A31),1) -> 46054 | I31: =$C31*$D31*(1+$E31) -> 249886.56 | J31: =I31*70% -> 174920.59 | K31: =I31-J31 -> 74965.968
A32: 46077 | B32: TX-100030 | C32: 12 | D32: 17890 | E32: 0.09 | F32: 1 | G32: 4 | H32: =DATE(YEAR($A32),MONTH($A32),1) -> 46054 | I32: =$C32*$D32*(1+$E32) -> 234001.2 | J32: =I32*70% -> 163800.84 | K32: =I32-J32 -> 70200.36
A33: 46199 | B33: TX-100031 | C33: 4 | D33: 6009 | E33: 0.09 | F33: 4 | G33: 2 | H33: =DATE(YEAR($A33),MONTH($A33),1) -> 46174 | I33: =$C33*$D33*(1+$E33) -> 26199.24 | J33: =I33*70% -> 18339.468 | K33: =I33-J33 -> 7859.772
A34: 46344 | B34: TX-100032 | C34: 11 | D34: 23552 | E34: 0.04 | F34: 2 | G34: 1 | H34: =DATE(YEAR($A34),MONTH($A34),1) -> 46327 | I34: =$C34*$D34*(1+$E34) -> 269434.88 | J34: =I34*70% -> 188604.42 | K34: =I34-J34 -> 80830.464
A35: 46181 | B35: TX-100033 | C35: 4 | D35: 27730 | F35: 5 | G35: 4 | H35: =DATE(YEAR($A35),MONTH($A35),1) -> 46174 | I35: =$C35*$D35*(1+$E35) -> 110920 | J35: =I35*70% -> 77644 | K35: =I35-J35 -> 33276
A36: 46115 | B36: TX-100034 | C36: 6 | D36: 11824 | F36: 4 | G36: 2 | H36: =DATE(YEAR($A36),MONTH($A36),1) -> 46113 | I36: =$C36*$D36*(1+$E36) -> 70944 | J36: =I36*70% -> 49660.8 | K36: =I36-J36 -> 21283.2
A37: 46128 | B37: TX-100035 | C37: 4 | D37: 16635 | E37: 0.02 | F37: 3 | G37: 1 | H37: =DATE(YEAR($A37),MONTH($A37),1) -> 46113 | I37: =$C37*$D37*(1+$E37) -> 67870.8 | J37: =I37*70% -> 47509.56 | K37: =I37-J37 -> 20361.24
A38: 46365 | B38: TX-100036 | C38: 1 | D38: 24659 | E38: 0.1 | F38: 1 | G38: 3 | H38: =DATE(YEAR($A38),MONTH($A38),1) -> 46357 | I38: =$C38*$D38*(1+$E38) -> 27124.9 | J38: =I38*70% -> 18987.43 | K38: =I38-J38 -> 8137.47
A39: 46094 | B39: TX-100037 | C39: 1 | D39: 25492 | E39: 0.07 | F39: 3 | G39: 5 | H39: =DATE(YEAR($A39),MONTH($A39),1) -> 46082 | I39: =$C39*$D39*(1+$E39) -> 27276.44 | J39: =I39*70% -> 19093.508 | K39: =I39-J39 -> 8182.932
A40: 46381 | B40: TX-100038 | C40: 4 | D40: 15290 | E40: 0.05 | F40: 5 | G40: 8 | H40: =DATE(YEAR($A40),MONTH($A40),1) -> 46357 | I40: =$C40*$D40*(1+$E40) -> 64218 | J40: =I40*70% -> 44952.6 | K40: =I40-J40 -> 19265.4
...

Sheet Dim Clientes
A1: ID_Cliente | B1: Cliente
A2: 1 | B2: Cliente 1
A3: 2 | B3: Cliente 2
A4: 3 | B4: Cliente 3
A5: 4 | B5: Cliente 4
A6: 5 | B6: Cliente 5

Sheet Dim Productos
A1: ID_Producto | B1: Producto
A2: 1 | B2: Producto 1
A3: 2 | B3: Producto 2
A4: 3 | B4: Producto 3
A5: 4 | B5: Producto 4
A6: 5 | B6: Producto 5
A7: 6 | B7: Producto 6
A8: 7 | B8: Producto 7
A9: 8 | B9: Producto 8

Sheet Dim Calendario
A1: Fecha | B1: Año | C1: Mes_Nro | D1: Mes | E1: Trimestre
A2: 46023 | B2: 2026 | C2: 1 | D2: ene | E2: T1
A3: 46024 | B3: 2026 | C3: 1 | D3: ene | E3: T1
A4: 46025 | B4: 2026 | C4: 1 | D4: ene | E4: T1
A5: 46026 | B5: 2026 | C5: 1 | D5: ene | E5: T1
A6: 46027 | B6: 2026 | C6: 1 | D6: ene | E6: T1
A7: 46028 | B7: 2026 | C7: 1 | D7: ene | E7: T1
A8: 46029 | B8: 2026 | C8: 1 | D8: ene | E8: T1
A9: 46030 | B9: 2026 | C9: 1 | D9: ene | E9: T1
A10: 46031 | B10: 2026 | C10: 1 | D10: ene | E10: T1
A11: 46032 | B11: 2026 | C11: 1 | D11: ene | E11: T1
A12: 46033 | B12: 2026 | C12: 1 | D12: ene | E12: T1
A13: 46034 | B13: 2026 | C13: 1 | D13: ene | E13: T1
... A366: 46387 | B366: 2026 | C366: 12 | D366: dic | E366: T4

Sheet Modelo Estrella
A1: Modelo en Estrella — Diseño Relacional
A5: DIM: Tbl_Clientes | D5: FACT: Ventas_Limpias | G5: DIM: Tbl_Productos
A6: PK | B6: ID_Cliente | D6: PK | E6: ID_Transaccion | G6: PK | H6: ID_Producto
A7: Atributo | B7: Cliente | D7: FK | E7: ID_Cliente | G7: Atributo | H7: Producto
D8: FK | E8: ID_Producto
D9: FK | E9: Fecha_Operacion
D12: DIM: Tbl_Calendario
D13: PK | E13: Fecha
D14: Atributo | E14: Año
D15: Atributo | E15: Mes
D16: Atributo | E16: Trimestre
A19: Relación | B19: Cardinalidad | C19: Dirección de filtro
A20: Tbl_Clientes[ID_Cliente] → Ventas_Limpias[ID_Cliente] | B20: 1:N | C20: Dimensión → Hechos
A21: Tbl_Productos[ID_Producto] → Ventas_Limpias[ID_Producto] | B21: 1:N | C21: Dimensión → Hechos
A22: Tbl_Calendario[Fecha] → Ventas_Limpias[Fecha_Operacion] | B22: 1:N | C22: Dimensión → Hechos

Sheet Código M y DAX
A1: Código documentado — Power Query M y DAX
A3: Consulta M: Ventas_Limpias
A4: let
A5: // ETL local sobre la tabla de ventas del libro
A6: Origen = Excel.CurrentWorkbook(){[Name="Tbl_Dataset"]}[Content],
A7: TiposCorregidos = Table.TransformColumnTypes(Origen, {{"Fecha_Operacion", type date}, {"ID_Transaccion", type text}, {"Bultos", Int64.Type}, {"Precio_Mayorista", Currency.Type}, {"Impuesto_Interno", Percentage.Type}, {"ID_Cliente", Int64.Type}, {"ID_Producto", Int64.Type}, {"Mes_Operacion", type text}, {"Venta_Total", Currency.Type}}),
A8: SinNulos = Table.SelectRows(TiposCorregidos, each [ID_Transaccion] <> null and [Venta_Total] <> null),
A9: VentasFiltradas = Table.SelectRows(SinNulos, each [Bultos] > 0 and [Venta_Total] > 0)
A10: in
A11: VentasFiltradas
A14: Medidas DAX optimizadas
A15: Medida | B15: Código DAX
A16: Total Ventas | B16: Total Ventas := SUM(Ventas_Limpias[Venta_Total])
A17: Costo Estimado | B17: Costo Estimado := SUM(Ventas_Limpias[Costo_Estimado])
A18: Margen Neto | B18: Margen Neto := VAR Ventas = [Total Ventas] VAR Costos = [Costo Estimado] RETURN Ventas - Costos
A19: Margen Neto % | B19: Margen Neto % := VAR Ventas = [Total Ventas] VAR Margen = [Margen Neto] RETURN DIVIDE(Margen, Ventas, 0)
A20: Ticket Promedio | B20: Ticket Promedio := VAR Ventas = [Total Ventas] VAR Operaciones = DISTINCTCOUNT(Ventas_Limpias[ID_Transaccion]) RETURN DIVIDE(Ventas, Operaciones, 0)
A23: Activación final en Excel
A24: 1 | B24: Datos → Obtener datos → Consulta en blanco → Editor avanzado: pegar el bloque M.
A25: 2 | B25: Cerrar y cargar en… → Solo crear conexión → Agregar estos datos al Modelo de Datos.
A26: 3 | B26: Power Pivot → Administrar → Vista de diagrama: crear las tres relaciones 1:N documentadas.
A27: 4 | B27: Crear las medidas usando el código DAX de esta hoja.
A28: 5 | B28: Guardar como PreEntrega_ModeloBI_PereyraNatalia.xlsx o .xlsb.

Sheet Estadística Descriptiva
A1: Estadística descriptiva — Venta Total
A3: Métrica | B3: Resultado
A4: Cantidad | B4: =COUNT('Dataset Principal'!I2:I5001) -> 5000
A5: Media | B5: =AVERAGE('Dataset Principal'!I2:I5001) -> 126590.96
A6: Mediana | B6: =MEDIAN('Dataset Principal'!I2:I5001) -> 99448.12
A7: Desvío estándar | B7: =_xlfn.STDEV.S('Dataset Principal'!I2:I5001) -> 99995.514
A8: Mínimo | B8: =MIN('Dataset Principal'!I2:I5001) -> 1619
A9: Máximo | B9: =MAX('Dataset Principal'!I2:I5001) -> 474354
A10: Rango | B10: =B9-B8 -> 472735
A11: Suma | B11: =SUM('Dataset Principal'!I2:I5001) -> 6.3295482e+08
A13: Lectura ejecutiva
A14: La mediana es inferior a la media, señal de operaciones grandes que elevan el promedio.
A15: El rango refleja una dispersión amplia en el importe por transacción.

Sheet Tabla dinámica del escenario
A1: $B$12:$D$12 por | B1: (Todas)
A3: Etiquetas de fila | B3: $G$12
A4: Base | B4: 1.8988645e+08
A5: Optimista | B5: 2.6805637e+08
A6: Pesimista | B6: 1.2247676e+08

Sheet Resumen de Escenarios
A1: Resumen de Escenarios y Objetivo
A3: Supuesto base | B3: Valor
A4: Unidades / bultos | B4: 32873
A5: Precio unitario promedio | B5: =SUM('Dataset Principal'!I2:I5001)/B4 -> 19254.55
A6: Costo unitario base | B6: =B5*70% -> 13478.185
A7: Beneficio objetivo | B7: 5000000
A8: Unidades requeridas | B8: =B7/(B5-B6) -> 865.59627
A11: Escenario | B11: Factor precio | C11: Factor costo | D11: Factor demanda | E11: Ventas | F11: Costos | G11: Beneficio
A12: Pesimista | B12: 0.95 | C12: 1.05 | D12: 0.9 | E12: =$B$4*D12*$B$5*B12 -> 5.4117637e+08 | F12: =$B$4*D12*$B$6*C12 -> 4.1869961e+08 | G12: =E12-F12 -> 1.2247676e+08
A13: Base | B13: 1 | C13: 1 | D13: 1 | E13: =$B$4*D13*$B$5*B13 -> 6.3295482e+08 | F13: =$B$4*D13*$B$6*C13 -> 4.4306838e+08 | G13: =E13-F13 -> 1.8988645e+08
A14: Optimista | B14: 1.05 | C14: 0.95 | D14: 1.1 | E14: =$B$4*D14*$B$5*B14 -> 7.3106282e+08 | F14: =$B$4*D14*$B$6*C14 -> 4.6300645e+08 | G14: =E14-F14 -> 2.6805637e+08
A17: Buscar objetivo equivalente: cambiar unidades hasta que Beneficio alcance $5.000.000.
A19: Búsqueda de objetivo | B19: Valor
A20: Unidades a calcular | B20: 865.59627
A21: Beneficio calculado | B21: =B20*($B$5-$B$6) -> 5000000
A22: Beneficio objetivo | B22: 5000000

Sheet Datos Dashboard
A1: Mes | B1: Producto | C1: Cliente | D1: Venta_Total | E1: Costo_Estimado | F1: Margen_Neto | G1: Bultos | H1: Visible
A2: 2026-08 | B2: Producto 1 | C2: Cliente 2 | D2: 18994.56 | E2: 13296.192 | F2: 5698.368 | G2: 6 | H2: =SUBTOTAL(103,A2) -> 1
A3: 2026-05 | B3: Producto 2 | C3: Cliente 4 | D3: 69563.7 | E3: 48694.59 | F3: 20869.11 | G3: 5 | H3: =SUBTOTAL(103,A3) -> 1
A4: 2026-02 | B4: Producto 3 | C4: Cliente 4 | D4: 23411.7 | E4: 16388.19 | F4: 7023.51 | G4: 2 | H4: =SUBTOTAL(103,A4) -> 1
A5: 2026-04 | B5: Producto 4 | C5: Cliente 4 | D5: 20355.75 | E5: 14249.025 | F5: 6106.725 | G5: 9 | H5: =SUBTOTAL(103,A5) -> 1
A6: 2026-06 | B6: Producto 5 | C6: Cliente 5 | D6: 82318.68 | E6: 57623.076 | F6: 24695.604 | G6: 3 | H6: =SUBTOTAL(103,A6) -> 1
A7: 2026-12 | B7: Producto 6 | C7: Cliente 2 | D7: 298089.2 | E7: 208662.44 | F7: 89426.76 | G7: 8 | H7: =SUBTOTAL(103,A7) -> 1
A8: 2026-11 | B8: Producto 5 | C8: Cliente 1 | D8: 142264.72 | E8: 99585.304 | F8: 42679.416 | G8: 4 | H8: =SUBTOTAL(103,A8) -> 1
A9: 2026-08 | B9: Producto 5 | C9: Cliente 5 | D9: 34644 | E9: 24250.8 | F9: 10393.2 | G9: 6 | H9: =SUBTOTAL(103,A9) -> 1
A10: 2026-12 | B10: Producto 6 | C10: Cliente 1 | D10: 239679 | E10: 167775.3 | F10: 71903.7 | G10: 11 | H10: =SUBTOTAL(103,A10) -> 1
A11: 2026-09 | B11: Producto 2 | C11: Cliente 5 | D11: 34543.2 | E11: 24180.24 | F11: 10362.96 | G11: 1 | H11: =SUBTOTAL(103,A11) -> 1
A12: 2026-05 | B12: Producto 5 | C12: Cliente 5 | D12: 94705 | E12: 66293.5 | F12: 28411.5 | G12: 5 | H12: =SUBTOTAL(103,A12) -> 1
A13: 2026-09 | B13: Producto 7 | C13: Cliente 1 | D13: 31358.35 | E13: 21950.845 | F13: 9407.505 | G13: 5 | H13: =SUBTOTAL(103,A13) -> 1
... A5001: 2026-03 | B5001: Producto 5 | C5001: Cliente 4 | D5001: 262317 | E5001: 183621.9 | F5001: 78695.1 | G5001: 11 | H5001: =SUBTOTAL(103,A5001) -> 1

Sheet Dashboard Final
A1: Dashboard Comercial 2026 | Z1: Mes | AA1: Ventas | AB1: Costo | AC1: Margen | AD1: Clave Pivot | AG1: Producto | AH1: Ventas | AJ1: Cliente | AK1: Ventas | AZ1: Mes | BA1: Producto | BB1: Cliente | BC1: Venta_Total | BD1: Costo_Estimado | BE1: Margen_Neto | BF1: Bultos
Z2: 46023 | AA2: =SUMIFS(tblDashFiltro[Venta_Total],tblDashFiltro[Mes],$AD2,tblDashFiltro[Visible],1) -> 51147001 | AB2: =SUMIFS(tblDashFiltro[Costo_Estimado],tblDashFiltro[Mes],$AD2,tblDashFiltro[Visible],1) -> 35802901 | AC2: =SUMIFS(tblDashFiltro[Margen_Neto],tblDashFiltro[Mes],$AD2,tblDashFiltro[Visible],1) -> 15344100 | AD2: 2026-01 | AG2: Producto 1 | AH2: =SUMIFS(tblDashFiltro[Venta_Total],tblDashFiltro[Producto],AG2,tblDashFiltro[Visible],1) -> 80861486 | AJ2: Cliente 1 | AK2: =SUMIFS(tblDashFiltro[Venta_Total],tblDashFiltro[Cliente],AJ2,tblDashFiltro[Visible],1) -> 1.2159391e+08 | AZ2: 2026-08 | BA2: Producto 1 | BB2: Cliente 2 | BC2: 18994.56 | BD2: 13296.192 | BE2: 5698.368 | BF2: 6
A3: ="Vista filtrada | "&SUBTOTAL(103,tblDashFiltro[Mes])&" operaciones | "&COUNTIF($AA$2:$AA$13,">0")&IF(COUNTIF($AA$2:$AA$13,">0")=1," mes | "," meses | ")&COUNTIF($AH$2:$AH$9,">0")&IF(COUNTIF($AH$2:$AH$9,">0")=1," producto | "," productos | ")&COUNTIF($AK$2:$AK$6,">0")&IF(COUNTIF($AK$2:$AK$6,">0")=1," cliente"," clientes") -> Vista filtrada | 5000 operaciones | 12 meses | 8 productos | 5 clientes | Z3: 46054 | AA3: =SUMIFS(tblDashFiltro[Venta_Total],tblDashFiltro[Mes],$AD3,tblDashFiltro[Visible],1) -> 55597128 | AB3: =SUMIFS(tblDashFiltro[Costo_Estimado],tblDashFiltro[Mes],$AD3,tblDashFiltro[Visible],1) -> 38917989 | AC3: =SUMIFS(tblDashFiltro[Margen_Neto],tblDashFiltro[Mes],$AD3,tblDashFiltro[Visible],1) -> 16679138 | AD3: 2026-02 | AG3: Producto 2 | AH3: =SUMIFS(tblDashFiltro[Venta_Total],tblDashFiltro[Producto],AG3,tblDashFiltro[Visible],1) -> 76452491 | AJ3: Cliente 2 | AK3: =SUMIFS(tblDashFiltro[Venta_Total],tblDashFiltro[Cliente],AJ3,tblDashFiltro[Visible],1) -> 1.3258341e+08 | AZ3: 2026-05 | BA3: Producto 2 | BB3: Cliente 4 | BC3: 69563.7 | BD3: 48694.59 | BE3: 20869.11 | BF3: 5
Z4: 46082 | AA4: =SUMIFS(tblDashFiltro[Venta_Total],tblDashFiltro[Mes],$AD4,tblDashFiltro[Visible],1) -> 49850424 | AB4: =SUMIFS(tblDashFiltro[Costo_Estimado],tblDashFiltro[Mes],$AD4,tblDashFiltro[Visible],1) -> 34895297 | AC4: =SUMIFS(tblDashFiltro[Margen_Neto],tblDashFiltro[Mes],$AD4,tblDashFiltro[Visible],1) -> 14955127 | AD4: 2026-03 | AG4: Producto 3 | AH4: =SUMIFS(tblDashFiltro[Venta_Total],tblDashFiltro[Producto],AG4,tblDashFiltro[Visible],1) -> 77873096 | AJ4: Cliente 3 | AK4: =SUMIFS(tblDashFiltro[Venta_Total],tblDashFiltro[Cliente],AJ4,tblDashFiltro[Visible],1) -> 1.2716917e+08 | AZ4: 2026-02 | BA4: Producto 3 | BB4: Cliente 4 | BC4: 23411.7 | BD4: 16388.19 | BE4: 7023.51 | BF4: 2
A5: VENTAS TOTALES | F5: MARGEN NETO % | K5: CRECIMIENTO YoY | Z5: 46113 | AA5: =SUMIFS(tblDashFiltro[Venta_Total],tblDashFiltro[Mes],$AD5,tblDashFiltro[Visible],1) -> 50017999 | AB5: =SUMIFS(tblDashFiltro[Costo_Estimado],tblDashFiltro[Mes],$AD5,tblDashFiltro[Visible],1) -> 35012600 | AC5: =SUMIFS(tblDashFiltro[Margen_Neto],tblDashFiltro[Mes],$AD5,tblDashFiltro[Visible],1) -> 15005400 | AD5: 2026-04 | AG5: Producto 4 | AH5: =SUMIFS(tblDashFiltro[Venta_Total],tblDashFiltro[Producto],AG5,tblDashFiltro[Visible],1) -> 77674840 | AJ5: Cliente 4 | AK5: =SUMIFS(tblDashFiltro[Venta_Total],tblDashFiltro[Cliente],AJ5,tblDashFiltro[Visible],1) -> 1.2740488e+08 | AZ5: 2026-04 | BA5: Producto 4 | BB5: Cliente 4 | BC5: 20355.75 | BD5: 14249.025 | BE5: 6106.725 | BF5: 9
A6: =SUBTOTAL(109,tblDashFiltro[Venta_Total]) -> 6.3295482e+08 | F6: =IFERROR(SUBTOTAL(109,tblDashFiltro[Margen_Neto])/SUBTOTAL(109,tblDashFiltro[Venta_Total]),0) -> 0.3 | K6: N/D | Z6: 46143 | AA6: =SUMIFS(tblDashFiltro[Venta_Total],tblDashFiltro[Mes],$AD6,tblDashFiltro[Visible],1) -> 53661071 | AB6: =SUMIFS(tblDashFiltro[Costo_Estimado],tblDashFiltro[Mes],$AD6,tblDashFiltro[Visible],1) -> 37562750 | AC6: =SUMIFS(tblDashFiltro[Margen_Neto],tblDashFiltro[Mes],$AD6,tblDashFiltro[Visible],1) -> 16098321 | AD6: 2026-05 | AG6: Producto 5 | AH6: =SUMIFS(tblDashFiltro[Venta_Total],tblDashFiltro[Producto],AG6,tblDashFiltro[Visible],1) -> 77252117 | AJ6: Cliente 5 | AK6: =SUMIFS(tblDashFiltro[Venta_Total],tblDashFiltro[Cliente],AJ6,tblDashFiltro[Visible],1) -> 1.2420345e+08 | AZ6: 2026-06 | BA6: Producto 5 | BB6: Cliente 5 | BC6: 82318.68 | BD6: 57623.076 | BE6: 24695.604 | BF6: 3
Z7: 46174 | AA7: =SUMIFS(tblDashFiltro[Venta_Total],tblDashFiltro[Mes],$AD7,tblDashFiltro[Visible],1) -> 50613744 | AB7: =SUMIFS(tblDashFiltro[Costo_Estimado],tblDashFiltro[Mes],$AD7,tblDashFiltro[Visible],1) -> 35429621 | AC7: =SUMIFS(tblDashFiltro[Margen_Neto],tblDashFiltro[Mes],$AD7,tblDashFiltro[Visible],1) -> 15184123 | AD7: 2026-06 | AG7: Producto 6 | AH7: =SUMIFS(tblDashFiltro[Venta_Total],tblDashFiltro[Producto],AG7,tblDashFiltro[Visible],1) -> 81787539 | AZ7: 2026-12 | BA7: Producto 6 | BB7: Cliente 2 | BC7: 298089.2 | BD7: 208662.44 | BE7: 89426.76 | BF7: 8
Z8: 46204 | AA8: =SUMIFS(tblDashFiltro[Venta_Total],tblDashFiltro[Mes],$AD8,tblDashFiltro[Visible],1) -> 54996502 | AB8: =SUMIFS(tblDashFiltro[Costo_Estimado],tblDashFiltro[Mes],$AD8,tblDashFiltro[Visible],1) -> 38497552 | AC8: =SUMIFS(tblDashFiltro[Margen_Neto],tblDashFiltro[Mes],$AD8,tblDashFiltro[Visible],1) -> 16498951 | AD8: 2026-07 | AG8: Producto 7 | AH8: =SUMIFS(tblDashFiltro[Venta_Total],tblDashFiltro[Producto],AG8,tblDashFiltro[Visible],1) -> 82404026 | AZ8: 2026-11 | BA8: Producto 5 | BB8: Cliente 1 | BC8: 142264.72 | BD8: 99585.304 | BE8: 42679.416 | BF8: 4
Z9: 46235 | AA9: =SUMIFS(tblDashFiltro[Venta_Total],tblDashFiltro[Mes],$AD9,tblDashFiltro[Visible],1) -> 56742403 | AB9: =SUMIFS(tblDashFiltro[Costo_Estimado],tblDashFiltro[Mes],$AD9,tblDashFiltro[Visible],1) -> 39719682 | AC9: =SUMIFS(tblDashFiltro[Margen_Neto],tblDashFiltro[Mes],$AD9,tblDashFiltro[Visible],1) -> 17022721 | AD9: 2026-08 | AG9: Producto 8 | AH9: =SUMIFS(tblDashFiltro[Venta_Total],tblDashFiltro[Producto],AG9,tblDashFiltro[Visible],1) -> 78649226 | AZ9: 2026-08 | BA9: Producto 5 | BB9: Cliente 5 | BC9: 34644 | BD9: 24250.8 | BE9: 10393.2 | BF9: 6
Z10: 46266 | AA10: =SUMIFS(tblDashFiltro[Venta_Total],tblDashFiltro[Mes],$AD10,tblDashFiltro[Visible],1) -> 49489162 | AB10: =SUMIFS(tblDashFiltro[Costo_Estimado],tblDashFiltro[Mes],$AD10,tblDashFiltro[Visible],1) -> 34642413 | AC10: =SUMIFS(tblDashFiltro[Margen_Neto],tblDashFiltro[Mes],$AD10,tblDashFiltro[Visible],1) -> 14846749 | AD10: 2026-09 | AZ10: 2026-12 | BA10: Producto 6 | BB10: Cliente 1 | BC10: 239679 | BD10: 167775.3 | BE10: 71903.7 | BF10: 11
Z11: 46296 | AA11: =SUMIFS(tblDashFiltro[Venta_Total],tblDashFiltro[Mes],$AD11,tblDashFiltro[Visible],1) -> 54656574 | AB11: =SUMIFS(tblDashFiltro[Costo_Estimado],tblDashFiltro[Mes],$AD11,tblDashFiltro[Visible],1) -> 38259602 | AC11: =SUMIFS(tblDashFiltro[Margen_Neto],tblDashFiltro[Mes],$AD11,tblDashFiltro[Visible],1) -> 16396972 | AD11: 2026-10 | AZ11: 2026-09 | BA11: Producto 2 | BB11: Cliente 5 | BC11: 34543.2 | BD11: 24180.24 | BE11: 10362.96 | BF11: 1
Z12: 46327 | AA12: =SUMIFS(tblDashFiltro[Venta_Total],tblDashFiltro[Mes],$AD12,tblDashFiltro[Visible],1) -> 51519994 | AB12: =SUMIFS(tblDashFiltro[Costo_Estimado],tblDashFiltro[Mes],$AD12,tblDashFiltro[Visible],1) -> 36063996 | AC12: =SUMIFS(tblDashFiltro[Margen_Neto],tblDashFiltro[Mes],$AD12,tblDashFiltro[Visible],1) -> 15455998 | AD12: 2026-11 | AZ12: 2026-05 | BA12: Producto 5 | BB12: Cliente 5 | BC12: 94705 | BD12: 66293.5 | BE12: 28411.5 | BF12: 5
Z13: 46357 | AA13: =SUMIFS(tblDashFiltro[Venta_Total],tblDashFiltro[Mes],$AD13,tblDashFiltro[Visible],1) -> 53359350 | AB13: =SUMIFS(tblDashFiltro[Costo_Estimado],tblDashFiltro[Mes],$AD13,tblDashFiltro[Visible],1) -> 37351545 | AC13: =SUMIFS(tblDashFiltro[Margen_Neto],tblDashFiltro[Mes],$AD13,tblDashFiltro[Visible],1) -> 16007805 | AD13: 2026-12 | AZ13: 2026-09 | BA13: Producto 7 | BB13: Cliente 1 | BC13: 31358.35 | BD13: 21950.845 | BE13: 9407.505 | BF13: 5
AZ14: 2026-07 | BA14: Producto 2 | BB14: Cliente 4 | BC14: 273593.6 | BD14: 191515.52 | BE14: 82078.08 | BF14: 8
AZ15: 2026-09 | BA15: Producto 1 | BB15: Cliente 5 | BC15: 266133 | BD15: 186293.1 | BE15: 79839.9 | BF15: 10
AZ16: 2026-06 | BA16: Producto 1 | BB16: Cliente 2 | BC16: 9471.88 | BD16: 6630.316 | BE16: 2841.564 | BF16: 4
AZ17: 2026-10 | BA17: Producto 4 | BB17: Cliente 5 | BC17: 31790 | BD17: 22253 | BE17: 9537 | BF17: 10
AZ18: 2026-03 | BA18: Producto 3 | BB18: Cliente 4 | BC18: 127525.44 | BD18: 89267.808 | BE18: 38257.632 | BF18: 7
AZ19: 2026-10 | BA19: Producto 3 | BB19: Cliente 5 | BC19: 55750.86 | BD19: 39025.602 | BE19: 16725.258 | BF19: 3
AZ20: 2026-02 | BA20: Producto 8 | BB20: Cliente 3 | BC20: 30855.24 | BD20: 21598.668 | BE20: 9256.572 | BF20: 2
AZ21: 2026-05 | BA21: Producto 7 | BB21: Cliente 3 | BC21: 5564.45 | BD21: 3895.115 | BE21: 1669.335 | BF21: 1
AZ22: 2026-04 | BA22: Producto 1 | BB22: Cliente 2 | BC22: 178981 | BD22: 125286.7 | BE22: 53694.3 | BF22: 10
AZ23: 2026-10 | BA23: Producto 1 | BB23: Cliente 1 | BC23: 13092 | BD23: 9164.4 | BE23: 3927.6 | BF23: 1
AZ24: 2026-10 | BA24: Producto 8 | BB24: Cliente 3 | BC24: 263680 | BD24: 184576 | BE24: 79104 | BF24: 10
AZ25: 2026-08 | BA25: Producto 4 | BB25: Cliente 4 | BC25: 213850 | BD25: 149695 | BE25: 64155 | BF25: 10
A26: 3 CONCLUSIONES BASADAS EN LOS DATOS | I26: ABOGADO DEL DIABLO — REVISIÓN CHATGPT | AZ26: 2026-07 | BA26: Producto 3 | BB26: Cliente 2 | BC26: 116940 | BD26: 81858 | BE26: 35082 | BF26: 5
A27: =IF(SUM($AA$2:$AA$13)=0,"1. No hay operaciones para la combinación seleccionada.","1. "&TEXT(INDEX($Z$2:$Z$13,MATCH(MAX($AA$2:$AA$13),$AA$2:$AA$13,0)),"mmmm")&" lidera con $"&ROUND(MAX($AA$2:$AA$13)/1000000,2)&" M ("&ROUND(100*MAX($AA$2:$AA$13)/SUM($AA$2:$AA$13),1)&"%) de las ventas fechadas visibles.") -> 1. agosto lidera con $56,74 M (9%) de las ventas fechadas visibles. | I27: =IF(SUBTOTAL(103,tblDashFiltro[Mes])<30,"Objeción 1 → La selección contiene solo "&SUBTOTAL(103,tblDashFiltro[Mes])&" operaciones; el mes líder puede ser sensible a pocos casos.","Objeción 1 → Un solo año no permite separar estacionalidad de variación aleatoria; no debe asumirse que el mes líder se repetirá.") -> Objeción 1 → Un solo año no permite separar estacionalidad de variación aleatoria; no debe asumirse que el mes líder se repetirá. | AZ27: 2026-04 | BA27: Producto 6 | BB27: Cliente 1 | BC27: 32533.2 | BD27: 22773.24 | BE27: 9759.96 | BF27: 12
AZ28: 2026-03 | BA28: Producto 2 | BB28: Cliente 2 | BC28: 26134 | BD28: 18293.8 | BE28: 7840.2 | BF28: 2
AZ29: 2026-04 | BA29: Producto 7 | BB29: Cliente 4 | BC29: 188504 | BD29: 131952.8 | BE29: 56551.2 | BF29: 8
AZ30: 2026-09 | BA30: Producto 8 | BB30: Cliente 4 | BC30: 285763.5 | BD30: 200034.45 | BE30: 85729.05 | BF30: 10
A31: =IF(SUM($AH$2:$AH$9)=0,"2. No hay productos con ventas para la selección.","2. "&INDEX($AG$2:$AG$9,MATCH(MAX($AH$2:$AH$9),$AH$2:$AH$9,0))&" lidera con $"&ROUND(MAX($AH$2:$AH$9)/1000000,2)&" M ("&ROUND(100*MAX($AH$2:$AH$9)/SUM($AH$2:$AH$9),1)&"%) de la selección.") -> 2. Producto 7 lidera con $82,4 M (13%) de la selección. | I31: ="Objeción 2 → El liderazgo de "&IFERROR(INDEX($AG$2:$AG$9,MATCH(MAX($AH$2:$AH$9),$AH$2:$AH$9,0)),"un producto")&" es por ventas, no por rentabilidad: el costo está modelado como 70% para todos." -> Objeción 2 → El liderazgo de Producto 7 es por ventas, no por rentabilidad: el costo está modelado como 70% para todos. | AZ31: 2026-02 | BA31: Producto 6 | BB31: Cliente 2 | BC31: 249886.56 | BD31: 174920.59 | BE31: 74965.968 | BF31: 11
AZ32: 2026-02 | BA32: Producto 4 | BB32: Cliente 1 | BC32: 234001.2 | BD32: 163800.84 | BE32: 70200.36 | BF32: 12
AZ33: 2026-06 | BA33: Producto 2 | BB33: Cliente 4 | BC33: 26199.24 | BD33: 18339.468 | BE33: 7859.772 | BF33: 4
AZ34: 2026-11 | BA34: Producto 1 | BB34: Cliente 2 | BC34: 269434.88 | BD34: 188604.42 | BE34: 80830.464 | BF34: 11
A35: =IF(SUM($AK$2:$AK$6)=0,"3. No hay clientes con ventas para la selección.","3. "&INDEX($AJ$2:$AJ$6,MATCH(MAX($AK$2:$AK$6),$AK$2:$AK$6,0))&" concentra $"&ROUND(MAX($AK$2:$AK$6)/1000000,2)&" M ("&ROUND(100*MAX($AK$2:$AK$6)/SUM($AK$2:$AK$6),1)&"%) de la selección.") -> 3. Cliente 2 concentra $132,58 M (20,9%) de la selección. | I35: ="Objeción 3 → La concentración en "&IFERROR(INDEX($AJ$2:$AJ$6,MATCH(MAX($AK$2:$AK$6),$AK$2:$AK$6,0)),"un cliente")&" no captura región, canal ni solvencia; esas variables no existen en el modelo." -> Objeción 3 → La concentración en Cliente 2 no captura región, canal ni solvencia; esas variables no existen en el modelo. | AZ35: 2026-06 | BA35: Producto 4 | BB35: Cliente 5 | BC35: 110920 | BD35: 77644 | BE35: 33276 | BF35: 4
AZ36: 2026-04 | BA36: Producto 2 | BB36: Cliente 4 | BC36: 70944 | BD36: 49660.8 | BE36: 21283.2 | BF36: 6
AZ37: 2026-04 | BA37: Producto 1 | BB37: Cliente 3 | BC37: 67870.8 | BD37: 47509.56 | BE37: 20361.24 | BF37: 4
AZ38: 2026-12 | BA38: Producto 3 | BB38: Cliente 1 | BC38: 27124.9 | BD38: 18987.43 | BE38: 8137.47 | BF38: 1
AZ39: 2026-03 | BA39: Producto 5 | BB39: Cliente 3 | BC39: 27276.44 | BD39: 19093.508 | BE39: 8182.932 | BF39: 1
A40: Nota metodológica: 5.000 operaciones de 2026. El margen de 30,0% es modelado (costo estimado = 70% de ventas). YoY se mantiene como N/D porque no existe un año previo. Ambos gráficos, KPIs, resumen mensual y narrativa responden a Mes, Producto y Cliente; se usan estos filtros porque no existen Categoría ni Región. | AZ40: 2026-12 | BA40: Producto 8 | BB40: Cliente 5 | BC40: 64218 | BD40: 44952.6 | BE40: 19265.4 | BF40: 4
...
